Workbook

Sheet Summary
A1: Team | B1: Bracket | C1: Group | D1: W | E1: D | F1: L | G1: Pts | H1: GF | I1: GA | J1: GD | K1: Form (recent->older)
A2: Germany | B2: Left | C2: E | D2: =COUNTIFS('All Matches'!$A:$A,$A2,'All Matches'!$J:$J,"W") -> 9 | E2: =COUNTIFS('All Matches'!$A:$A,$A2,'All Matches'!$J:$J,"D") -> 0 | F2: =COUNTIFS('All Matches'!$A:$A,$A2,'All Matches'!$J:$J,"L") -> 1 | G2: =D2*3+E2 -> 27 | H2: =SUMIFS('All Matches'!$H:$H,'All Matches'!$A:$A,$A2) -> 31 | I2: =SUMIFS('All Matches'!$I:$I,'All Matches'!$A:$A,$A2) -> 9 | J2: =H2-I2 -> 22 | K2: LWWWWWWWWW
A3: Paraguay | B3: Left | D3: =COUNTIFS('All Matches'!$A:$A,$A3,'All Matches'!$J:$J,"W") -> 4 | E3: =COUNTIFS('All Matches'!$A:$A,$A3,'All Matches'!$J:$J,"D") -> 2 | F3: =COUNTIFS('All Matches'!$A:$A,$A3,'All Matches'!$J:$J,"L") -> 4 | G3: =D3*3+E3 -> 14 | H3: =SUMIFS('All Matches'!$H:$H,'All Matches'!$A:$A,$A3) -> 13 | I3: =SUMIFS('All Matches'!$I:$I,'All Matches'!$A:$A,$A3) -> 13 | J3: =H3-I3 -> 0 | K3: DWLWLWWLLD
A4: France | B4: Left | C4: I | D4: =COUNTIFS('All Matches'!$A:$A,$A4,'All Matches'!$J:$J,"W") -> 8 | E4: =COUNTIFS('All Matches'!$A:$A,$A4,'All Matches'!$J:$J,"D") -> 1 | F4: =COUNTIFS('All Matches'!$A:$A,$A4,'All Matches'!$J:$J,"L") -> 1 | G4: =D4*3+E4 -> 25 | H4: =SUMIFS('All Matches'!$H:$H,'All Matches'!$A:$A,$A4) -> 28 | I4: =SUMIFS('All Matches'!$I:$I,'All Matches'!$A:$A,$A4) -> 10 | J4: =H4-I4 -> 18 | K4: WWWWLWWWWD
A5: Sweden | B5: Left | C5: F | D5: =COUNTIFS('All Matches'!$A:$A,$A5,'All Matches'!$J:$J,"W") -> 3 | E5: =COUNTIFS('All Matches'!$A:$A,$A5,'All Matches'!$J:$J,"D") -> 3 | F5: =COUNTIFS('All Matches'!$A:$A,$A5,'All Matches'!$J:$J,"L") -> 4 | G5: =D5*3+E5 -> 12 | H5: =SUMIFS('All Matches'!$H:$H,'All Matches'!$A:$A,$A5) -> 18 | I5: =SUMIFS('All Matches'!$I:$I,'All Matches'!$A:$A,$A5) -> 21 | J5: =H5-I5 -> -3 | K5: DLWDLWWDLL
A6: South Africa | B6: Left | C6: A | D6: =COUNTIFS('All Matches'!$A:$A,$A6,'All Matches'!$J:$J,"W") -> 2 | E6: =COUNTIFS('All Matches'!$A:$A,$A6,'All Matches'!$J:$J,"D") -> 4 | F6: =COUNTIFS('All Matches'!$A:$A,$A6,'All Matches'!$J:$J,"L") -> 4 | G6: =D6*3+E6 -> 10 | H6: =SUMIFS('All Matches'!$H:$H,'All Matches'!$A:$A,$A6) -> 9 | I6: =SUMIFS('All Matches'!$I:$I,'All Matches'!$A:$A,$A6) -> 12 | J6: =H6-I6 -> -3 | K6: WDLDDLDLWL
A7: Canada | B7: Left | C7: B | D7: =COUNTIFS('All Matches'!$A:$A,$A7,'All Matches'!$J:$J,"W") -> 4 | E7: =COUNTIFS('All Matches'!$A:$A,$A7,'All Matches'!$J:$J,"D") -> 5 | F7: =COUNTIFS('All Matches'!$A:$A,$A7,'All Matches'!$J:$J,"L") -> 1 | G7: =D7*3+E7 -> 17 | H7: =SUMIFS('All Matches'!$H:$H,'All Matches'!$A:$A,$A7) -> 16 | I7: =SUMIFS('All Matches'!$I:$I,'All Matches'!$A:$A,$A7) -> 6 | J7: =H7-I7 -> 10 | K7: LWDDWDDWWD
A8: Netherlands | B8: Left | C8: F | D8: =COUNTIFS('All Matches'!$A:$A,$A8,'All Matches'!$J:$J,"W") -> 6 | E8: =COUNTIFS('All Matches'!$A:$A,$A8,'All Matches'!$J:$J,"D") -> 3 | F8: =COUNTIFS('All Matches'!$A:$A,$A8,'All Matches'!$J:$J,"L") -> 1 | G8: =D8*3+E8 -> 21 | H8: =SUMIFS('All Matches'!$H:$H,'All Matches'!$A:$A,$A8) -> 24 | I8: =SUMIFS('All Matches'!$I:$I,'All Matches'!$A:$A,$A8) -> 9 | J8: =H8-I8 -> 15 | K8: WWDWLDWWDW
A9: Morocco | B9: Left | C9: C | D9: =COUNTIFS('All Matches'!$A:$A,$A9,'All Matches'!$J:$J,"W") -> 6 | E9: =COUNTIFS('All Matches'!$A:$A,$A9,'All Matches'!$J:$J,"D") -> 3 | F9: =COUNTIFS('All Matches'!$A:$A,$A9,'All Matches'!$J:$J,"L") -> 1 | G9: =D9*3+E9 -> 21 | H9: =SUMIFS('All Matches'!$H:$H,'All Matches'!$A:$A,$A9) -> 16 | I9: =SUMIFS('All Matches'!$I:$I,'All Matches'!$A:$A,$A9) -> 7 | J9: =H9-I9 -> 9 | K9: WWDDWWDLWW
A10: Portugal | B10: Left | C10: K | D10: =COUNTIFS('All Matches'!$A:$A,$A10,'All Matches'!$J:$J,"W") -> 5 | E10: =COUNTIFS('All Matches'!$A:$A,$A10,'All Matches'!$J:$J,"D") -> 4 | F10: =COUNTIFS('All Matches'!$A:$A,$A10,'All Matches'!$J:$J,"L") -> 1 | G10: =D10*3+E10 -> 19 | H10: =SUMIFS('All Matches'!$H:$H,'All Matches'!$A:$A,$A10) -> 23 | I10: =SUMIFS('All Matches'!$I:$I,'All Matches'!$A:$A,$A10) -> 8 | J10: =H10-I10 -> 15 | K10: DWDWDWLDWW
A11: Croatia | B11: Left | C11: L | D11: =COUNTIFS('All Matches'!$A:$A,$A11,'All Matches'!$J:$J,"W") -> 7 | E11: =COUNTIFS('All Matches'!$A:$A,$A11,'All Matches'!$J:$J,"D") -> 0 | F11: =COUNTIFS('All Matches'!$A:$A,$A11,'All Matches'!$J:$J,"L") -> 3 | G11: =D11*3+E11 -> 21 | H11: =SUMIFS('All Matches'!$H:$H,'All Matches'!$A:$A,$A11) -> 19 | I11: =SUMIFS('All Matches'!$I:$I,'All Matches'!$A:$A,$A11) -> 15 | J11: =H11-I11 -> 4 | K11: WWLWLLWWWW
A12: Spain | B12: Left | C12: H | D12: =COUNTIFS('All Matches'!$A:$A,$A12,'All Matches'!$J:$J,"W") -> 6 | E12: =COUNTIFS('All Matches'!$A:$A,$A12,'All Matches'!$J:$J,"D") -> 4 | F12: =COUNTIFS('All Matches'!$A:$A,$A12,'All Matches'!$J:$J,"L") -> 0 | G12: =D12*3+E12 -> 22 | H12: =SUMIFS('All Matches'!$H:$H,'All Matches'!$A:$A,$A12) -> 22 | I12: =SUMIFS('All Matches'!$I:$I,'All Matches'!$A:$A,$A12) -> 4 | J12: =H12-I12 -> 18 | K12: WWDWDDWDWW
A13: Austria | B13: Left | C13: J | D13: =COUNTIFS('All Matches'!$A:$A,$A13,'All Matches'!$J:$J,"W") -> 7 | E13: =COUNTIFS('All Matches'!$A:$A,$A13,'All Matches'!$J:$J,"D") -> 2 | F13: =COUNTIFS('All Matches'!$A:$A,$A13,'All Matches'!$J:$J,"L") -> 1 | G13: =D13*3+E13 -> 23 | H13: =SUMIFS('All Matches'!$H:$H,'All Matches'!$A:$A,$A13) -> 27 | I13: =SUMIFS('All Matches'!$I:$I,'All Matches'!$A:$A,$A13) -> 8 | J13: =H13-I13 -> 19 | K13: DLWWWWDWWW
A14: United States | B14: Left | C14: D | D14: =COUNTIFS('All Matches'!$A:$A,$A14,'All Matches'!$J:$J,"W") -> 6 | E14: =COUNTIFS('All Matches'!$A:$A,$A14,'All Matches'!$J:$J,"D") -> 0 | F14: =COUNTIFS('All Matches'!$A:$A,$A14,'All Matches'!$J:$J,"L") -> 4 | G14: =D14*3+E14 -> 18 | H14: =SUMIFS('All Matches'!$H:$H,'All Matches'!$A:$A,$A14) -> 23 | I14: =SUMIFS('All Matches'!$I:$I,'All Matches'!$A:$A,$A14) -> 18 | J14: =H14-I14 -> 5 | K14: LWWLWLLWWW
A15: Bosnia & Herzegovina | B15: Left | C15: B | D15: =COUNTIFS('All Matches'!$A:$A,$A15,'All Matches'!$J:$J,"W") -> 5 | E15: =COUNTIFS('All Matches'!$A:$A,$A15,'All Matches'!$J:$J,"D") -> 4 | F15: =COUNTIFS('All Matches'!$A:$A,$A15,'All Matches'!$J:$J,"L") -> 1 | G15: =D15*3+E15 -> 19 | H15: =SUMIFS('All Matches'!$H:$H,'All Matches'!$A:$A,$A15) -> 16 | I15: =SUMIFS('All Matches'!$I:$I,'All Matches'!$A:$A,$A15) -> 12 | J15: =H15-I15 -> 4 | K15: WLDDDWWDWW
... A33: Ghana | B33: Right | C33: L | D33: =COUNTIFS('All Matches'!$A:$A,$A33,'All Matches'!$J:$J,"W") -> 4 | E33: =COUNTIFS('All Matches'!$A:$A,$A33,'All Matches'!$J:$J,"D") -> 2 | F33: =COUNTIFS('All Matches'!$A:$A,$A33,'All Matches'!$J:$J,"L") -> 4 | G33: =D33*3+E33 -> 14 | H33: =SUMIFS('All Matches'!$H:$H,'All Matches'!$A:$A,$A33) -> 12 | I33: =SUMIFS('All Matches'!$I:$I,'All Matches'!$A:$A,$A33) -> 12 | J33: =H33-I33 -> 0 | K33: LDWDLLLWWW

Sheet All Matches
A1: Team | B1: # | C1: Date | D1: Competition | E1: Venue | F1: Opponent | G1: Score | H1: GF | I1: GA | J1: Result | K1: Notes
A2: Germany | B2: 1 | C2: 2026-06-25 | D2: World Cup 2026 Group | E2: N | F2: Ecuador | G2: 1-2 | H2: 1 | I2: 2 | J2: L
A3: Germany | B3: 2 | C3: 2026-06-20 | D3: World Cup 2026 Group | E3: N | F3: Ivory Coast | G3: 2-1 | H3: 2 | I3: 1 | J3: W
A4: Germany | B4: 3 | C4: 2026-06-14 | D4: World Cup 2026 Group | E4: N | F4: Curacao | G4: 7-1 | H4: 7 | I4: 1 | J4: W
A5: Germany | B5: 4 | C5: 2026-06-06 | D5: Friendly | E5: A | F5: United States | G5: 2-1 | H5: 2 | I5: 1 | J5: W
A6: Germany | B6: 5 | C6: 2026-05-31 | D6: Friendly | E6: H | F6: Finland | G6: 4-0 | H6: 4 | I6: 0 | J6: W
A7: Germany | B7: 6 | C7: 2026-03-30 | D7: Friendly | E7: H | F7: Ghana | G7: 2-1 | H7: 2 | I7: 1 | J7: W
A8: Germany | B8: 7 | C8: 2026-03-27 | D8: Friendly | E8: A | F8: Switzerland | G8: 4-3 | H8: 4 | I8: 3 | J8: W
A9: Germany | B9: 8 | C9: 2025-11-17 | D9: WC Qualifier (UEFA) | E9: H | F9: Slovakia | G9: 6-0 | H9: 6 | I9: 0 | J9: W
A10: Germany | B10: 9 | C10: 2025-11-14 | D10: WC Qualifier (UEFA) | E10: A | F10: Luxembourg | G10: 2-0 | H10: 2 | I10: 0 | J10: W
A11: Germany | B11: 10 | C11: 2025-10-13 | D11: WC Qualifier (UEFA) | E11: H | F11: Northern Ireland | G11: 1-0 | H11: 1 | I11: 0 | J11: W
A12: Paraguay | B12: 1 | C12: 2026-06-25 | D12: World Cup 2026 Group | E12: N | F12: Australia | G12: 0-0 | H12: 0 | I12: 0 | J12: D
A13: Paraguay | B13: 2 | C13: 2026-06-19 | D13: World Cup 2026 Group | E13: N | F13: Turkiye | G13: 1-0 | H13: 1 | I13: 0 | J13: W
... A27: France | B27: 6 | C27: 2026-03-29 | D27: Friendly | E27: N | F27: Colombia | G27: 3-1 | H27: 3 | I27: 1 | J27: W
A28: France | B28: 7 | C28: 2026-03-26 | D28: Friendly | E28: N | F28: Brazil | G28: 2-1 | H28: 2 | I28: 1 | J28: W | K28: CORRECTED: France won (was drafted as a loss)
A29: France | B29: 8 | C29: 2025-11-16 | D29: WC Qualifier (UEFA) | E29: H | F29: Azerbaijan | G29: 3-1 | H29: 3 | I29: 1 | J29: W
A30: France | B30: 9 | C30: 2025-11-13 | D30: WC Qualifier (UEFA) | E30: H | F30: Ukraine | G30: 4-0 | H30: 4 | I30: 0 | J30: W
A31: France | B31: 10 | C31: 2025-10-13 | D31: WC Qualifier (UEFA) | E31: H | F31: Iceland | G31: 2-2 | H31: 2 | I31: 2 | J31: D
A32: Sweden | B32: 1 | C32: 2026-06-26 | D32: World Cup 2026 Group | E32: N | F32: Japan | G32: 1-1 | H32: 1 | I32: 1 | J32: D
A33: Sweden | B33: 2 | C33: 2026-06-20 | D33: World Cup 2026 Group | E33: N | F33: Netherlands | G33: 1-5 | H33: 1 | I33: 5 | J33: L
A34: Sweden | B34: 3 | C34: 2026-06-14 | D34: World Cup 2026 Group | E34: N | F34: Tunisia | G34: 5-1 | H34: 5 | I34: 1 | J34: W
A35: Sweden | B35: 4 | C35: 2026-06-04 | D35: Friendly | E35: A | F35: Greece | G35: 2-2 | H35: 2 | I35: 2 | J35: D
A36: Sweden | B36: 5 | C36: 2026-06-01 | D36: Friendly | E36: A | F36: Norway | G36: 1-3 | H36: 1 | I36: 3 | J36: L
A37: Sweden | B37: 6 | C37: 2026-03-31 | D37: WC Qual Playoff Final | E37: H | F37: Poland | G37: 3-2 | H37: 3 | I37: 2 | J37: W
A38: Sweden | B38: 7 | C38: 2026-03-26 | D38: WC Qual Playoff SF | E38: N | F38: Ukraine | G38: 3-1 | H38: 3 | I38: 1 | J38: W | K38: Ukraine nominal host (played in Spain)
A39: Sweden | B39: 8 | C39: 2025-11-18 | D39: WC Qualifier (UEFA) | E39: A | F39: Slovenia | G39: 1-1 | H39: 1 | I39: 1 | J39: D
A40: Sweden | B40: 9 | C40: 2025-11-15 | D40: WC Qualifier (UEFA) | E40: A | F40: Switzerland | G40: 1-4 | H40: 1 | I40: 4 | J40: L
A41: Sweden | B41: 10 | C41: 2025-10-13 | D41: WC Qualifier (UEFA) | E41: H | F41: Kosovo | G41: 0-1 | H41: 0 | I41: 1 | J41: L | K41: CORRECTED: Sweden lost at home (was drafted as a win)
A42: South Africa | B42: 1 | C42: 2026-06-24 | D42: World Cup 2026 Group | E42: N | F42: South Korea | G42: 1-0 | H42: 1 | I42: 0 | J42: W
A43: South Africa | B43: 2 | C43: 2026-06-18 | D43: World Cup 2026 Group | E43: N | F43: Czechia | G43: 1-1 | H43: 1 | I43: 1 | J43: D
A44: South Africa | B44: 3 | C44: 2026-06-11 | D44: World Cup 2026 Group | E44: N | F44: Mexico | G44: 0-2 | H44: 0 | I44: 2 | J44: L
A45: South Africa | B45: 4 | C45: 2026-06-06 | D45: Friendly | E45: N | F45: Jamaica | G45: 1-1 | H45: 1 | I45: 1 | J45: D | K45: CORRECTED to 1-1 (early reports said 0-1)
A46: South Africa | B46: 5 | C46: 2026-05-29 | D46: Friendly | E46: N | F46: Nicaragua | G46: 0-0 | H46: 0 | I46: 0 | J46: D
A47: South Africa | B47: 6 | C47: 2026-03-31 | D47: Friendly | E47: N | F47: Panama | G47: 1-2 | H47: 1 | I47: 2 | J47: L
A48: South Africa | B48: 7 | C48: 2026-03-27 | D48: Friendly | E48: N | F48: Panama | G48: 1-1 | H48: 1 | I48: 1 | J48: D
A49: South Africa | B49: 8 | C49: 2026-01-04 | D49: AFCON 2025 R16 | E49: N | F49: Cameroon | G49: 1-2 | H49: 1 | I49: 2 | J49: L
A50: South Africa | B50: 9 | C50: 2025-12-29 | D50: AFCON 2025 Group | E50: N | F50: Zimbabwe | G50: 3-2 | H50: 3 | I50: 2 | J50: W
A51: South Africa | B51: 10 | C51: 2025-12-26 | D51: AFCON 2025 Group | E51: N | F51: Egypt | G51: 0-1 | H51: 0 | I51: 1 | J51: L
A52: Canada | B52: 1 | C52: 2026-06-24 | D52: World Cup 2026 Group | E52: N | F52: Switzerland | G52: 1-2 | H52: 1 | I52: 2 | J52: L
A53: Canada | B53: 2 | C53: 2026-06-18 | D53: World Cup 2026 Group | E53: N | F53: Qatar | G53: 6-0 | H53: 6 | I53: 0 | J53: W
...

Sheet Read Me & Caveats
A1: World Cup 2026 - Last 10 Matches per Knockout-Round Team (VERIFIED)
A2: Compiled and independently re-verified June 28, 2026. Teams are the 32 sides in the FOX 2026 knockout bracket.
A4: Verification: every one of the 320 matches was checked a second time against an independent source (Wikipedia team & 2026 World Cup pages, FBref, FIFA.com, UEFA/CAF, ESPN, national federations).
A6: Corrections applied in this pass:
A7: RESULTS THAT CHANGED (W/D/L):
A8: - France 2-1 Brazil (Mar 26) - France actually WON (had been recorded as a loss).
A9: - Belgium 2-0 Croatia (Jun 2) - Belgium WON; Croatia's row corrected to a 0-2 loss.
A10: - Belgium 4-2 Wales (Oct 13) - Belgium WON away (had been a loss).
A11: - Bosnia & Herzegovina 4-1 Malta (Oct 12) - Bosnia WON (score had been from Malta's side).
A12: - Sweden 0-1 Kosovo (Oct 13) - Sweden LOST at home (had been a win).
A13: - Portugal 0-2 Republic of Ireland (Nov 13) - Portugal LOST in Dublin (had been a home win).
A14: - South Africa 1-1 Jamaica (Jun 6) - corrected to a draw.
... A28: - Penalty-shootout games show the regulation score with the outcome in Notes. Round-of-32 knockout games (late June/July) are not yet completed and are excluded.
